Workbook

Sheet Property Value Estimates
A1: Property Value Estimates — Sample Buildings, Nihonbashi District 2
A3: ASSUMPTIONS — Property Value Rate by Use Type (¥/m²)
A4: Use Type | B4: Rate (¥/m²) | C4: Basis / Source
A5: Office | B5: 2795000 | C5: Office Grade B Tokyo 23-ku: ¥7,338/m²/mo (CBRE Q1 2026) × 12 ÷ 3.15% office cap rate (CBRE Q1 2026)
A6: Residence & Commercial Mixed | B6: =AVERAGE(B5,B7) -> 2309000 | C6: Placeholder: average of Office and Apartment rates, pending per-building floor-use mix from occupancy data
A7: Apartment | B7: 1823000 | C7: Residential, SUUMO Nihonbashi: ¥5,469/m²/mo × 12 ÷ 3.60% avg residential cap rate (CBRE Q1 2026)
A8: Public | B8: =B5 -> 2795000 | C8: Placeholder for renovation-cost estimation: public buildings aren't market-traded, so this links to the Office rate (civic/institutional buildings are typically built to office-grade specs). Replace once building-specific data is available.
A10: BUILDING SAMPLE — 22 Buildings, District 2
A11: ID | B11: Use Type | C11: Use Code | D11: Floors | E11: Height (m) | F11: Footprint Area (m²) | G11: GFA (m²) | H11: Value Rate (¥/m²) | I11: Est. Property Value (¥) | J11: Est. Property Value (¥M) | K11: Site/Lot Area (m²) | L11: FAR (Current) | M11: Built Year | N11: Tier (Age-Based)
A12: 2070 | B12: Office | C12: 121 | D12: 5 | E12: 29.7 | F12: 82.1072 | G12: =F12*D12 -> 410.536 | H12: =VLOOKUP(B12,$A$5:$B$8,2,FALSE()) -> 2795000 | I12: =G12*H12 -> 1.1474481e+09 | J12: =I12/1000000 -> 1147.4481 | K12: 82.1072 | L12: =G12/K12 -> 5 | M12: =VLOOKUP(A12,'Building Age & Tier'!$A$12:$I$33,7,FALSE()) -> 2019 | N12: =VLOOKUP(A12,'Building Age & Tier'!$A$12:$I$33,9,FALSE()) -> Maintenance
A13: 2563 | B13: Residence & Commercial Mixed | C13: 123 | D13: 2 | E13: 30 | F13: 41.0505 | G13: =F13*D13 -> 82.101 | H13: =VLOOKUP(B13,$A$5:$B$8,2,FALSE()) -> 2309000 | I13: =G13*H13 -> 1.8957121e+08 | J13: =I13/1000000 -> 189.57121 | K13: 41.0505 | L13: =G13/K13 -> 2 | M13: =VLOOKUP(A13,'Building Age & Tier'!$A$12:$I$33,7,FALSE()) -> 0 | N13: =VLOOKUP(A13,'Building Age & Tier'!$A$12:$I$33,9,FALSE()) -> TBD
A14: 3037 | B14: Office | C14: 121 | D14: 4 | E14: 18.3 | F14: 888.05705 | G14: =F14*D14 -> 3552.2282 | H14: =VLOOKUP(B14,$A$5:$B$8,2,FALSE()) -> 2795000 | I14: =G14*H14 -> 9.9284778e+09 | J14: =I14/1000000 -> 9928.4778 | K14: 888.05705 | L14: =G14/K14 -> 4 | M14: =VLOOKUP(A14,'Building Age & Tier'!$A$12:$I$33,7,FALSE()) -> 1967 | N14: =VLOOKUP(A14,'Building Age & Tier'!$A$12:$I$33,9,FALSE()) -> Reconstruct
A15: 3042 | B15: Office | C15: 121 | D15: 6 | E15: 26.8 | F15: 555.54198 | G15: =F15*D15 -> 3333.2519 | H15: =VLOOKUP(B15,$A$5:$B$8,2,FALSE()) -> 2795000 | I15: =G15*H15 -> 9.316439e+09 | J15: =I15/1000000 -> 9316.439 | K15: 555.54198 | L15: =G15/K15 -> 6 | M15: =VLOOKUP(A15,'Building Age & Tier'!$A$12:$I$33,7,FALSE()) -> 0 | N15: =VLOOKUP(A15,'Building Age & Tier'!$A$12:$I$33,9,FALSE()) -> TBD
A16: 3044 | B16: Office | C16: 121 | D16: 6 | E16: 19.9 | F16: 88.1355 | G16: =F16*D16 -> 528.813 | H16: =VLOOKUP(B16,$A$5:$B$8,2,FALSE()) -> 2795000 | I16: =G16*H16 -> 1.4780323e+09 | J16: =I16/1000000 -> 1478.0323 | K16: 88.1355 | L16: =G16/K16 -> 6 | M16: =VLOOKUP(A16,'Building Age & Tier'!$A$12:$I$33,7,FALSE()) -> 2010 | N16: =VLOOKUP(A16,'Building Age & Tier'!$A$12:$I$33,9,FALSE()) -> Maintenance
A17: 3065 | B17: Residence & Commercial Mixed | C17: 123 | D17: 3 | E17: 9.2 | F17: 59.1759 | G17: =F17*D17 -> 177.5277 | H17: =VLOOKUP(B17,$A$5:$B$8,2,FALSE()) -> 2309000 | I17: =G17*H17 -> 4.0991146e+08 | J17: =I17/1000000 -> 409.91146 | K17: 59.1759 | L17: =G17/K17 -> 3 | M17: =VLOOKUP(A17,'Building Age & Tier'!$A$12:$I$33,7,FALSE()) -> 0 | N17: =VLOOKUP(A17,'Building Age & Tier'!$A$12:$I$33,9,FALSE()) -> TBD
A18: 3067 | B18: Office | C18: 121 | D18: 2 | E18: 24.6 | F18: 25.498839 | G18: =F18*D18 -> 50.997678 | H18: =VLOOKUP(B18,$A$5:$B$8,2,FALSE()) -> 2795000 | I18: =G18*H18 -> 1.4253851e+08 | J18: =I18/1000000 -> 142.53851 | K18: 25.498839 | L18: =G18/K18 -> 2 | M18: =VLOOKUP(A18,'Building Age & Tier'!$A$12:$I$33,7,FALSE()) -> 1995 | N18: =VLOOKUP(A18,'Building Age & Tier'!$A$12:$I$33,9,FALSE()) -> Renovate
A19: 3074 | B19: Residence & Commercial Mixed | C19: 123 | D19: 8 | E19: 30.2 | F19: 72.9603 | G19: =F19*D19 -> 583.6824 | H19: =VLOOKUP(B19,$A$5:$B$8,2,FALSE()) -> 2309000 | I19: =G19*H19 -> 1.3477227e+09 | J19: =I19/1000000 -> 1347.7227 | K19: 72.9603 | L19: =G19/K19 -> 8 | M19: =VLOOKUP(A19,'Building Age & Tier'!$A$12:$I$33,7,FALSE()) -> 1998 | N19: =VLOOKUP(A19,'Building Age & Tier'!$A$12:$I$33,9,FALSE()) -> Renovate
A20: 3078 | B20: Office | C20: 121 | D20: 5 | E20: 22.5 | F20: 127.20825 | G20: =F20*D20 -> 636.04125 | H20: =VLOOKUP(B20,$A$5:$B$8,2,FALSE()) -> 2795000 | I20: =G20*H20 -> 1.7777353e+09 | J20: =I20/1000000 -> 1777.7353 | K20: 127.20825 | L20: =G20/K20 -> 5 | M20: =VLOOKUP(A20,'Building Age & Tier'!$A$12:$I$33,7,FALSE()) -> 1962 | N20: =VLOOKUP(A20,'Building Age & Tier'!$A$12:$I$33,9,FALSE()) -> Reconstruct
A21: 3486 | B21: Apartment | C21: 132 | D21: 9 | E21: 27.4 | F21: 52.139568 | G21: =F21*D21 -> 469.25611 | H21: =VLOOKUP(B21,$A$5:$B$8,2,FALSE()) -> 1823000 | I21: =G21*H21 -> 8.5545389e+08 | J21: =I21/1000000 -> 855.45389 | K21: 52.139568 | L21: =G21/K21 -> 9 | M21: =VLOOKUP(A21,'Building Age & Tier'!$A$12:$I$33,7,FALSE()) -> 2009 | N21: =VLOOKUP(A21,'Building Age & Tier'!$A$12:$I$33,9,FALSE()) -> Maintenance
A22: 3550 | B22: Office | C22: 121 | D22: 6 | E22: 24.1 | F22: 145.8984 | G22: =F22*D22 -> 875.3904 | H22: =VLOOKUP(B22,$A$5:$B$8,2,FALSE()) -> 2795000 | I22: =G22*H22 -> 2.4467162e+09 | J22: =I22/1000000 -> 2446.7162 | K22: 145.8984 | L22: =G22/K22 -> 6 | M22: =VLOOKUP(A22,'Building Age & Tier'!$A$12:$I$33,7,FALSE()) -> 1968 | N22: =VLOOKUP(A22,'Building Age & Tier'!$A$12:$I$33,9,FALSE()) -> Reconstruct
A23: 3552 | B23: Residence & Commercial Mixed | C23: 123 | D23: 2 | E23: 8.9 | F23: 54.6582 | G23: =F23*D23 -> 109.3164 | H23: =VLOOKUP(B23,$A$5:$B$8,2,FALSE()) -> 2309000 | I23: =G23*H23 -> 2.5241157e+08 | J23: =I23/1000000 -> 252.41157 | K23: 54.6582 | L23: =G23/K23 -> 2 | M23: =VLOOKUP(A23,'Building Age & Tier'!$A$12:$I$33,7,FALSE()) -> 2020 | N23: =VLOOKUP(A23,'Building Age & Tier'!$A$12:$I$33,9,FALSE()) -> Maintenance
... A33: 5050 | B33: Office | C33: 121 | D33: 6 | E33: 27.5 | F33: 48.753282 | G33: =F33*D33 -> 292.51969 | H33: =VLOOKUP(B33,$A$5:$B$8,2,FALSE()) -> 2795000 | I33: =G33*H33 -> 8.1759254e+08 | J33: =I33/1000000 -> 817.59254 | K33: 48.753282 | L33: =G33/K33 -> 6 | M33: =VLOOKUP(A33,'Building Age & Tier'!$A$12:$I$33,7,FALSE()) -> 1975 | N33: =VLOOKUP(A33,'Building Age & Tier'!$A$12:$I$33,9,FALSE()) -> Reconstruct
A34: TOTAL | G34: =SUM(G12:G33) -> 25315.935 | I34: =SUM(I12:I33) -> 6.9744521e+10 | J34: =SUM(J12:J33) -> 69744.521 | K34: =SUM(K12:K33) -> 4127.3674 | L34: =AVERAGE(L12:L33) -> 5.5909091
A35: Note: Public building (id 5039) uses the Office rate as a renovation-cost placeholder (see Assumptions). Its value is included in totals below — replace the Public rate in the Assumptions block once a building-specific estimate is available.
A37: SUMMARY BY USE TYPE
A38: Use Type | B38: Count | C38: Total GFA (m²) | D38: Total Est. Value (¥M) | E38: Avg FAR
A39: Office | B39: =COUNTIF($B$12:$B$33,A39) -> 15 | C39: =SUMIF($B$12:$B$33,A39,$G$12:$G$33) -> 23165.565 | D39: =SUMIF($B$12:$B$33,A39,$J$12:$J$33) -> 64747.755 | E39: =AVERAGEIF($B$12:$B$33,A39,$L$12:$L$33) -> 6.2
A40: Residence & Commercial Mixed | B40: =COUNTIF($B$12:$B$33,A40) -> 5 | C40: =SUMIF($B$12:$B$33,A40,$G$12:$G$33) -> 1146.9135 | D40: =SUMIF($B$12:$B$33,A40,$J$12:$J$33) -> 2648.2233 | E40: =AVERAGEIF($B$12:$B$33,A40,$L$12:$L$33) -> 3.6
A41: Apartment | B41: =COUNTIF($B$12:$B$33,A41) -> 1 | C41: =SUMIF($B$12:$B$33,A41,$G$12:$G$33) -> 469.25611 | D41: =SUMIF($B$12:$B$33,A41,$J$12:$J$33) -> 855.45389 | E41: =AVERAGEIF($B$12:$B$33,A41,$L$12:$L$33) -> 9
A42: Public | B42: =COUNTIF($B$12:$B$33,A42) -> 1 | C42: =SUMIF($B$12:$B$33,A42,$G$12:$G$33) -> 534.1997 | D42: =SUMIF($B$12:$B$33,A42,$J$12:$J$33) -> 1493.0882 | E42: =AVERAGEIF($B$12:$B$33,A42,$L$12:$L$33) -> 3
A43: TOTAL | B43: =SUM(B39:B42) -> 22 | C43: =SUM(C39:C42) -> 25315.935 | D43: =SUM(D39:D42) -> 69744.521 | E43: =AVERAGE(L12:L33) -> 5.5909091
A45: METHODOLOGY NOTES
A46: GFA (m²) = Footprint Area (m²) × Floors. This assumes a constant floor plate across all stories; treat as a first-order approximation.
A47: Value Rate is looked up by Use Type from the Assumptions block above — update the blue cells there to re-run all 22 buildings instantly.
A48: "Residence & Commercial Mixed" uses a placeholder rate (average of Office and Apartment). Replace with a floor-area-weighted rate per
A49: building once per-floor use mix is available from occupancy data.
A50: "Public" (id 5039) has no market value, so its rate is a placeholder linked to the Office rate, for renovation-cost estimation only.
A51: Update the Public rate cell directly if a more building-specific renovation-cost basis becomes available.
A52: Rates derived from CBRE Q1 2026 (Office, Cap Rates) and SUUMO Nihonbashi listings (Residential); see Assumptions block for full citations.
A53: FAR (Current) = GFA / Site-Lot Area. Site/Lot Area defaults to Footprint Area (blue, editable) as a placeholder — replace with actual
...

Sheet Building Age & Tier
A1: Building Age & Tier Classification — matched via footprint geometry (Shape_Area / Shape_Leng / Floors)
A3: TIER CLASSIFICATION CRITERIA (Alorabi et al., 2025) | G3: Current Year (for age calc) | H3: 2026
A4: Tier | B4: Built Year ≤ | C4: Age at Threshold (yrs) | D4: Typical Age | E4: Required Action
A5: Reconstruct | B5: 1980 | C5: =$H$3-B5 -> 46 | D5: 40+ years | E5: Demolish & Rebuild
A6: Renovate | B6: 2000 | C6: =$H$3-B6 -> 26 | D6: 20-40 years | E6: Structural/System Upgrades
A7: Maintenance | B7: > 2000 | D7: < 20 years | E7: Maintain; Energy Upgrades
A10: BUILDING AGE MATCH — 22 Buildings
A11: ID | B11: Use Type | C11: Floors | D11: Match Status | E11: Matched KEYID (ages file) | F11: Ages MainUse (QA) | G11: Built Year | H11: Building Age (yrs) | I11: Tier (Age-Based)
A12: 2070 | B12: Office | C12: 5 | D12: Matched (Δarea < 0.001 m²) | E12: 232 | F12: Office | G12: 2019 | H12: =IF(G12="","TBD",$H$3-G12) -> 7 | I12: =IF(G12="","TBD",IF(G12<=$B$5,"Reconstruct",IF(G12<=$B$6,"Renovate","Maintenance"))) -> Maintenance
A13: 2563 | B13: Residence & Commercial Mixed | C13: 2 | D13: No match found — verify manually | H13: =IF(G13="","TBD",$H$3-G13) -> TBD | I13: =IF(G13="","TBD",IF(G13<=$B$5,"Reconstruct",IF(G13<=$B$6,"Renovate","Maintenance"))) -> TBD
A14: 3037 | B14: Office | C14: 4 | D14: Matched (Δarea < 0.001 m²) | E14: 241 | F14: Office | G14: 1967 | H14: =IF(G14="","TBD",$H$3-G14) -> 59 | I14: =IF(G14="","TBD",IF(G14<=$B$5,"Reconstruct",IF(G14<=$B$6,"Renovate","Maintenance"))) -> Reconstruct
A15: 3042 | B15: Office | C15: 6 | D15: No match found — verify manually | H15: =IF(G15="","TBD",$H$3-G15) -> TBD | I15: =IF(G15="","TBD",IF(G15<=$B$5,"Reconstruct",IF(G15<=$B$6,"Renovate","Maintenance"))) -> TBD
A16: 3044 | B16: Office | C16: 6 | D16: Matched (Δarea < 0.001 m²) | E16: 226 | F16: Office | G16: 2010 | H16: =IF(G16="","TBD",$H$3-G16) -> 16 | I16: =IF(G16="","TBD",IF(G16<=$B$5,"Reconstruct",IF(G16<=$B$6,"Renovate","Maintenance"))) -> Maintenance
A17: 3065 | B17: Residence & Commercial Mixed | C17: 3 | D17: No match found — verify manually | H17: =IF(G17="","TBD",$H$3-G17) -> TBD | I17: =IF(G17="","TBD",IF(G17<=$B$5,"Reconstruct",IF(G17<=$B$6,"Renovate","Maintenance"))) -> TBD
A18: 3067 | B18: Office | C18: 2 | D18: Matched (Δarea < 0.001 m²) | E18: 252 | F18: Office | G18: 1995 | H18: =IF(G18="","TBD",$H$3-G18) -> 31 | I18: =IF(G18="","TBD",IF(G18<=$B$5,"Reconstruct",IF(G18<=$B$6,"Renovate","Maintenance"))) -> Renovate
A19: 3074 | B19: Residence & Commercial Mixed | C19: 8 | D19: Matched (Δarea < 0.001 m²) | E19: 242 | F19: Resid | G19: 1998 | H19: =IF(G19="","TBD",$H$3-G19) -> 28 | I19: =IF(G19="","TBD",IF(G19<=$B$5,"Reconstruct",IF(G19<=$B$6,"Renovate","Maintenance"))) -> Renovate
A20: 3078 | B20: Office | C20: 5 | D20: Matched (Δarea < 0.001 m²) | E20: 228 | F20: Office | G20: 1962 | H20: =IF(G20="","TBD",$H$3-G20) -> 64 | I20: =IF(G20="","TBD",IF(G20<=$B$5,"Reconstruct",IF(G20<=$B$6,"Renovate","Maintenance"))) -> Reconstruct
A21: 3486 | B21: Apartment | C21: 9 | D21: Matched (Δarea < 0.001 m²) | E21: 259 | F21: Resid | G21: 2009 | H21: =IF(G21="","TBD",$H$3-G21) -> 17 | I21: =IF(G21="","TBD",IF(G21<=$B$5,"Reconstruct",IF(G21<=$B$6,"Renovate","Maintenance"))) -> Maintenance
A22: 3550 | B22: Office | C22: 6 | D22: Matched (Δarea < 0.001 m²) | E22: 237 | F22: Office | G22: 1968 | H22: =IF(G22="","TBD",$H$3-G22) -> 58 | I22: =IF(G22="","TBD",IF(G22<=$B$5,"Reconstruct",IF(G22<=$B$6,"Renovate","Maintenance"))) -> Reconstruct
A23: 3552 | B23: Residence & Commercial Mixed | C23: 2 | D23: Matched (Δarea < 0.001 m²) | E23: 231 | F23: Resid | G23: 2020 | H23: =IF(G23="","TBD",$H$3-G23) -> 6 | I23: =IF(G23="","TBD",IF(G23<=$B$5,"Reconstruct",IF(G23<=$B$6,"Renovate","Maintenance"))) -> Maintenance
A24: 3554 | B24: Office | C24: 9 | D24: Matched (Δarea < 0.001 m²) | E24: 243 | F24: Office | G24: 1993 | H24: =IF(G24="","TBD",$H$3-G24) -> 33 | I24: =IF(G24="","TBD",IF(G24<=$B$5,"Reconstruct",IF(G24<=$B$6,"Renovate","Maintenance"))) -> Renovate
A25: 3562 | B25: Office | C25: 8 | D25: Matched (Δarea < 0.001 m²) | E25: 229 | F25: Office | G25: 1983 | H25: =IF(G25="","TBD",$H$3-G25) -> 43 | I25: =IF(G25="","TBD",IF(G25<=$B$5,"Reconstruct",IF(G25<=$B$6,"Renovate","Maintenance"))) -> Renovate
A26: 4050 | B26: Office | C26: 9 | D26: Matched (Δarea < 0.001 m²) | E26: 225 | F26: Office | G26: 1995 | H26: =IF(G26="","TBD",$H$3-G26) -> 31 | I26: =IF(G26="","TBD",IF(G26<=$B$5,"Reconstruct",IF(G26<=$B$6,"Renovate","Maintenance"))) -> Renovate
A27: 4062 | B27: Office | C27: 9 | D27: Matched (Δarea < 0.001 m²) | E27: 245 | F27: Office | G27: 1988 | H27: =IF(G27="","TBD",$H$3-G27) -> 38 | I27: =IF(G27="","TBD",IF(G27<=$B$5,"Reconstruct",IF(G27<=$B$6,"Renovate","Maintenance"))) -> Renovate
A28: 4560 | B28: Residence & Commercial Mixed | C28: 3 | D28: Matched (Δarea < 0.001 m²) | E28: 223 | F28: Resid | G28: 2004 | H28: =IF(G28="","TBD",$H$3-G28) -> 22 | I28: =IF(G28="","TBD",IF(G28<=$B$5,"Reconstruct",IF(G28<=$B$6,"Renovate","Maintenance"))) -> Maintenance
A29: 4562 | B29: Office | C29: 5 | D29: Matched (Δarea < 0.001 m²) | E29: 224 | F29: Office | G29: 1998 | H29: =IF(G29="","TBD",$H$3-G29) -> 28 | I29: =IF(G29="","TBD",IF(G29<=$B$5,"Reconstruct",IF(G29<=$B$6,"Renovate","Maintenance"))) -> Renovate
... A33: 5050 | B33: Office | C33: 6 | D33: Matched (Δarea < 0.001 m²) | E33: 239 | F33: Office | G33: 1975 | H33: =IF(G33="","TBD",$H$3-G33) -> 51 | I33: =IF(G33="","TBD",IF(G33<=$B$5,"Reconstruct",IF(G33<=$B$6,"Renovate","Maintenance"))) -> Reconstruct
A35: UNMATCHED BUILDINGS — MANUAL VERIFICATION NEEDED
A36: ID 2563 (Residence & Commercial Mixed, 2 floors, 41.05 m²): closest geometric candidate is KEYID 265 (5 floors, Office, 41.87 m², Δarea=0.82) — floor count mismatch, rejected.
A37: ID 3042 (Office, 6 floors, 555.54 m²): closest geometric candidate is KEYID 256 (9 floors, Office, 549.44 m², Δarea=6.10) — floor count mismatch, rejected.
A38: ID 3065 (Residence & Commercial Mixed, 3 floors, 59.18 m²): closest geometric candidate is KEYID 250 (4 floors, Office, 59.13 m², Δarea=0.05) — floor count mismatch, rejected.
A39: These 3 buildings may sit outside the 154-building "Building_EastModelDistrict_Curr" footprint, or have been re-surveyed/modified since that dataset was captured. Enter Built Year manually in column G (row above) once confirmed — Building Age and Tier will recalculate automatically.
A41: SUMMARY BY TIER
A42: Tier | B42: Count | C42: Total GFA (m²) | D42: Total Est. Value (¥M)
A43: Reconstruct | B43: =COUNTIF($I$12:$I$33,A43) -> 5 | C43: =SUMIF($I$12:$I$33,A43,'Property Value Estimates'!$G$12:$G$33) -> 5890.3792 | D43: =SUMIF($I$12:$I$33,A43,'Property Value Estimates'!$J$12:$J$33) -> 16463.61
A44: Renovate | B44: =COUNTIF($I$12:$I$33,A44) -> 9 | C44: =SUMIF($I$12:$I$33,A44,'Property Value Estimates'!$G$12:$G$33) -> 14120.467 | D44: =SUMIF($I$12:$I$33,A44,'Property Value Estimates'!$J$12:$J$33) -> 39183.037
A45: Maintenance | B45: =COUNTIF($I$12:$I$33,A45) -> 5 | C45: =SUMIF($I$12:$I$33,A45,'Property Value Estimates'!$G$12:$G$33) -> 1712.2075 | D45: =SUMIF($I$12:$I$33,A45,'Property Value Estimates'!$J$12:$J$33) -> 4181.9523
A46: TBD | B46: =COUNTIF($I$12:$I$33,A46) -> 3 | C46: =SUMIF($I$12:$I$33,A46,'Property Value Estimates'!$G$12:$G$33) -> 3592.8806 | D46: =SUMIF($I$12:$I$33,A46,'Property Value Estimates'!$J$12:$J$33) -> 9915.9217
A47: TOTAL | B47: =SUM(B43:B46) -> 22 | C47: =SUM(C43:C46) -> 25315.935 | D47: =SUM(D43:D46) -> 69744.521
A49: METHODOLOGY NOTES
...

Sheet Revitalization Cost
A1: Revitalization Cost Estimate — by Tier & GFA (illustrative, pre-teammate-data)
A3: COST ASSUMPTIONS — Revitalization Unit Cost by Tier (¥/m²)
A4: Base reconstruction unit cost (¥/m²) | E4: 302000 | F4: MLIT 2022 detached-house survey, prefab/steel-frame avg ¥302,655/m² (kojinjutaku_report_2022) — proxy for steel/RC office new-build
N5: 160.31
A6: Tier | B6: Scope of Work | C6: % of Reconstruction | D6: Unit Cost (¥/m²) | N6: 1*160.31
A7: Reconstruct | B7: Demolish & full rebuild; structure, envelope, services, finishes, external works | C7: 1 | D7: =$E$4*C7 -> 302000 | J7: kWh | K7: kWh | N7: convert to Yen | O7: convert to Yen | P7: convert to Yen | Q7: convert to Yen | R7: convert to Yen | S7: convert to Yen | T7: convert to Yen
A8: Renovate | B8: Envelope upgrade (R-value, U-value, WWR), HVAC replacement, programmatic/FAR changes | C8: 0.45 | D8: =$E$4*C8 -> 135900
A9: Maintenance | B9: Minor envelope, lighting retrofit, HVAC tuning, optional rooftop PV | C9: 0.15 | D9: =$E$4*C9 -> 45300 | J9: Annual Total Energy/GFA | K9: Annual Energy From Renewables/ GFA | L9: Carbon Emmissions Annual (Tonnes) W/DER | M9: Carbon Emmissions Annual (Tons) W/O DER | N9: DER Captial Expenditures | O9: Electrcity Bill W/DER | P9: Electrcity Bill W/O DER | Q9: Operation & Maintenance Cost W/O DER | R9: Operation & Maintenance Cost W/DER | S9: Energy Lifecycle Cost W/O DER | T9: Energy Lifecycle Cost W/DER
J10: 1264013 | K10: =J10*0.4 -> 505605.2 | L10: 197 | M10: 298 | N10: =423806*160.31 -> 67940340 | O10: =6408*160.31 -> 1027266.5 | P10: =11256* 160.31 -> 1804449.4 | Q10: 0 | R10: =19040.43* 160.31 -> 3052371.3 | S10: =3025977* 160.31 -> 4.8509437e+08 | T10: =2227050 * 160.31 -> 3.5701839e+08
A11: PER-BUILDING REVITALIZATION COST — 22 Buildings
A12: ID | B12: Use Type | C12: GFA (m²) | D12: Share of total Area | E12: Tier (Age-Based) | F12: Unit Cost (¥/m²) | G12: Est. Revitalization Cost (¥) | H12: Est. Cost (¥M) | I12: Cost per m² check | J12: Annual Total Energy/GFA | K12: Annual Energy From Renewables/ GFA | L12: Carbon Emmissions Annual (Tons) W/DER | M12: Carbon Emmissions Annual (Tons) W/O DER | N12: DER Captial Expenditures | O12: Energy Bill W/DER | P12: Energy Bill W/O DER | Q12: Operation & Maintenance Cost W/O DER | R12: Operation & Maintenance Cost W/DER | S12: Energy Lifecycle Cost W/O DER | T12: Energy Lifecycle Cost W/DER
A13: ='Property Value Estimates'!A12 -> 2070 | B13: ='Property Value Estimates'!B12 -> Office | C13: ='Property Value Estimates'!G12 -> 410.536 | D13: =C13/$C$35 -> 0.016216506 | E13: ='Property Value Estimates'!N12 -> Maintenance | F13: =IFERROR(VLOOKUP(E13,$A$7:$D$9,4,FALSE()),"TBD") -> 45300 | G13: =IF(ISNUMBER(F13),C13*F13,"TBD") -> 18597281 | H13: =IF(ISNUMBER(G13),G13/1000000,"TBD") -> 18.597281 | I13: =IF(ISNUMBER(G13),G13/C13,"TBD") -> 45300 | J13: =$J$10*D13 -> 20497.874 | K13: =$K$10*D13 -> 8199.1496 | L13: =$L$10*D13 -> 3.1946516 | M13: =$M$10*$D13 -> 4.8325187 | N13: =$N$10*D13 -> 1101754.9 | O13: =$O$10*$D13 -> 16658.673 | P13: =$P$10*$D13 -> 29261.863 | Q13: =$Q$10*$D13 -> 0 | R13: =$R$10*$D13 -> 49498.797 | S13: =$S$10*$D13 -> 7866535.7 | T13: =$T$10*$D13 -> 5789590.7
A14: ='Property Value Estimates'!A13 -> 2563 | B14: ='Property Value Estimates'!B13 -> Residence & Commercial Mixed | C14: ='Property Value Estimates'!G13 -> 82.101 | D14: =C14/$C$35 -> 0.0032430562 | E14: ='Property Value Estimates'!N13 -> TBD | F14: =IFERROR(VLOOKUP(E14,$A$7:$D$9,4,FALSE()),"TBD") -> TBD | G14: =IF(ISNUMBER(F14),C14*F14,"TBD") -> TBD | H14: =IF(ISNUMBER(G14),G14/1000000,"TBD") -> TBD | I14: =IF(ISNUMBER(G14),G14/C14,"TBD") -> TBD | J14: =$J$10*D14 -> 4099.2652 | K14: =$K$10*D14 -> 1639.7061 | L14: =$L$10*D14 -> 0.63888208 | M14: =$M$10*$D14 -> 0.96643076 | N14: =$N$10*D14 -> 220334.34 | O14: =$O$10*$D14 -> 3331.483 | P14: =$P$10*$D14 -> 5851.9307 | Q14: =$Q$10*$D14 -> 0 | R14: =$R$10*$D14 -> 9899.0119 | S14: =$S$10*$D14 -> 1573188.3 | T14: =$T$10*$D14 -> 1157830.7
A15: ='Property Value Estimates'!A14 -> 3037 | B15: ='Property Value Estimates'!B14 -> Office | C15: ='Property Value Estimates'!G14 -> 3552.2282 | D15: =C15/$C$35 -> 0.1403159 | E15: ='Property Value Estimates'!N14 -> Reconstruct | F15: =IFERROR(VLOOKUP(E15,$A$7:$D$9,4,FALSE()),"TBD") -> 302000 | G15: =IF(ISNUMBER(F15),C15*F15,"TBD") -> 1.0727729e+09 | H15: =IF(ISNUMBER(G15),G15/1000000,"TBD") -> 1072.7729 | I15: =IF(ISNUMBER(G15),G15/C15,"TBD") -> 302000 | J15: =$J$10*D15 -> 177361.12 | K15: =$K$10*D15 -> 70944.449 | L15: =$L$10*D15 -> 27.642233 | M15: =$M$10*$D15 -> 41.814139 | N15: =$N$10*D15 -> 9533110 | O15: =$O$10*$D15 -> 144141.82 | P15: =$P$10*$D15 -> 253192.94 | Q15: =$Q$10*$D15 -> 0 | R15: =$R$10*$D15 -> 428296.23 | S15: =$S$10*$D15 -> 68066454 | T15: =$T$10*$D15 -> 50095357
A16: ='Property Value Estimates'!A15 -> 3042 | B16: ='Property Value Estimates'!B15 -> Office | C16: ='Property Value Estimates'!G15 -> 3333.2519 | D16: =C16/$C$35 -> 0.13166616 | E16: ='Property Value Estimates'!N15 -> TBD | F16: =IFERROR(VLOOKUP(E16,$A$7:$D$9,4,FALSE()),"TBD") -> TBD | G16: =IF(ISNUMBER(F16),C16*F16,"TBD") -> TBD | H16: =IF(ISNUMBER(G16),G16/1000000,"TBD") -> TBD | I16: =IF(ISNUMBER(G16),G16/C16,"TBD") -> TBD | J16: =$J$10*D16 -> 166427.74 | K16: =$K$10*D16 -> 66571.095 | L16: =$L$10*D16 -> 25.938233 | M16: =$M$10*$D16 -> 39.236515 | N16: =$N$10*D16 -> 8945443.6 | O16: =$O$10*$D16 -> 135256.23 | P16: =$P$10*$D16 -> 237584.92 | Q16: =$Q$10*$D16 -> 0 | R16: =$R$10*$D16 -> 401894.01 | S16: =$S$10*$D16 -> 63870513 | T16: =$T$10*$D16 -> 47007239
A17: ='Property Value Estimates'!A16 -> 3044 | B17: ='Property Value Estimates'!B16 -> Office | C17: ='Property Value Estimates'!G16 -> 528.813 | D17: =C17/$C$35 -> 0.020888543 | E17: ='Property Value Estimates'!N16 -> Maintenance | F17: =IFERROR(VLOOKUP(E17,$A$7:$D$9,4,FALSE()),"TBD") -> 45300 | G17: =IF(ISNUMBER(F17),C17*F17,"TBD") -> 23955229 | H17: =IF(ISNUMBER(G17),G17/1000000,"TBD") -> 23.955229 | I17: =IF(ISNUMBER(G17),G17/C17,"TBD") -> 45300 | J17: =$J$10*D17 -> 26403.39 | K17: =$K$10*D17 -> 10561.356 | L17: =$L$10*D17 -> 4.115043 | M17: =$M$10*$D17 -> 6.2247859 | N17: =$N$10*D17 -> 1419174.7 | O17: =$O$10*$D17 -> 21458.1 | P17: =$P$10*$D17 -> 37692.319 | Q17: =$Q$10*$D17 -> 0 | R17: =$R$10*$D17 -> 63759.591 | S17: =$S$10*$D17 -> 10132915 | T17: =$T$10*$D17 -> 7457594
A18: ='Property Value Estimates'!A17 -> 3065 | B18: ='Property Value Estimates'!B17 -> Residence & Commercial Mixed | C18: ='Property Value Estimates'!G17 -> 177.5277 | D18: =C18/$C$35 -> 0.0070124884 | E18: ='Property Value Estimates'!N17 -> TBD | F18: =IFERROR(VLOOKUP(E18,$A$7:$D$9,4,FALSE()),"TBD") -> TBD | G18: =IF(ISNUMBER(F18),C18*F18,"TBD") -> TBD | H18: =IF(ISNUMBER(G18),G18/1000000,"TBD") -> TBD | I18: =IF(ISNUMBER(G18),G18/C18,"TBD") -> TBD | J18: =$J$10*D18 -> 8863.8766 | K18: =$K$10*D18 -> 3545.5506 | L18: =$L$10*D18 -> 1.3814602 | M18: =$M$10*$D18 -> 2.0897216 | N18: =$N$10*D18 -> 476430.85 | O18: =$O$10*$D18 -> 7203.6943 | P18: =$P$10*$D18 -> 12653.68 | Q18: =$Q$10*$D18 -> 0 | R18: =$R$10*$D18 -> 21404.719 | S18: =$S$10*$D18 -> 3401718.7 | T18: =$T$10*$D18 -> 2503587.3
A19: ='Property Value Estimates'!A18 -> 3067 | B19: ='Property Value Estimates'!B18 -> Office | C19: ='Property Value Estimates'!G18 -> 50.997678 | D19: =C19/$C$35 -> 0.0020144498 | E19: ='Property Value Estimates'!N18 -> Renovate | F19: =IFERROR(VLOOKUP(E19,$A$7:$D$9,4,FALSE()),"TBD") -> 135900 | G19: =IF(ISNUMBER(F19),C19*F19,"TBD") -> 6930584.5 | H19: =IF(ISNUMBER(G19),G19/1000000,"TBD") -> 6.9305845 | I19: =IF(ISNUMBER(G19),G19/C19,"TBD") -> 135900 | J19: =$J$10*D19 -> 2546.2907 | K19: =$K$10*D19 -> 1018.5163 | L19: =$L$10*D19 -> 0.3968466 | M19: =$M$10*$D19 -> 0.60030603 | N19: =$N$10*D19 -> 136862.4 | O19: =$O$10*$D19 -> 2069.3767 | P19: =$P$10*$D19 -> 3634.9726 | Q19: =$Q$10*$D19 -> 0 | R19: =$R$10*$D19 -> 6148.8487 | S19: =$S$10*$D19 -> 977198.24 | T19: =$T$10*$D19 -> 719195.6
A20: ='Property Value Estimates'!A19 -> 3074 | B20: ='Property Value Estimates'!B19 -> Residence & Commercial Mixed | C20: ='Property Value Estimates'!G19 -> 583.6824 | D20: =C20/$C$35 -> 0.023055929 | E20: ='Property Value Estimates'!N19 -> Renovate | F20: =IFERROR(VLOOKUP(E20,$A$7:$D$9,4,FALSE()),"TBD") -> 135900 | G20: =IF(ISNUMBER(F20),C20*F20,"TBD") -> 79322438 | H20: =IF(ISNUMBER(G20),G20/1000000,"TBD") -> 79.322438 | I20: =IF(ISNUMBER(G20),G20/C20,"TBD") -> 135900 | J20: =$J$10*D20 -> 29142.994 | K20: =$K$10*D20 -> 11657.198 | L20: =$L$10*D20 -> 4.5420181 | M20: =$M$10*$D20 -> 6.8706669 | N20: =$N$10*D20 -> 1566427.7 | O20: =$O$10*$D20 -> 23684.583 | P20: =$P$10*$D20 -> 41603.257 | Q20: =$Q$10*$D20 -> 0 | R20: =$R$10*$D20 -> 70375.257 | S20: =$S$10*$D20 -> 11184302 | T20: =$T$10*$D20 -> 8231390.6
A21: ='Property Value Estimates'!A20 -> 3078 | B21: ='Property Value Estimates'!B20 -> Office | C21: ='Property Value Estimates'!G20 -> 636.04125 | D21: =C21/$C$35 -> 0.025124146 | E21: ='Property Value Estimates'!N20 -> Reconstruct | F21: =IFERROR(VLOOKUP(E21,$A$7:$D$9,4,FALSE()),"TBD") -> 302000 | G21: =IF(ISNUMBER(F21),C21*F21,"TBD") -> 1.9208446e+08 | H21: =IF(ISNUMBER(G21),G21/1000000,"TBD") -> 192.08446 | I21: =IF(ISNUMBER(G21),G21/C21,"TBD") -> 302000 | J21: =$J$10*D21 -> 31757.248 | K21: =$K$10*D21 -> 12702.899 | L21: =$L$10*D21 -> 4.9494569 | M21: =$M$10*$D21 -> 7.4869956 | N21: =$N$10*D21 -> 1706943 | O21: =$O$10*$D21 -> 25809.193 | P21: =$P$10*$D21 -> 45335.25 | Q21: =$Q$10*$D21 -> 0 | R21: =$R$10*$D21 -> 76688.224 | S21: =$S$10*$D21 -> 12187582 | T21: =$T$10*$D21 -> 8969782.2
A22: ='Property Value Estimates'!A21 -> 3486 | B22: ='Property Value Estimates'!B21 -> Apartment | C22: ='Property Value Estimates'!G21 -> 469.25611 | D22: =C22/$C$35 -> 0.018535998 | E22: ='Property Value Estimates'!N21 -> Maintenance | F22: =IFERROR(VLOOKUP(E22,$A$7:$D$9,4,FALSE()),"TBD") -> 45300 | G22: =IF(ISNUMBER(F22),C22*F22,"TBD") -> 21257302 | H22: =IF(ISNUMBER(G22),G22/1000000,"TBD") -> 21.257302 | I22: =IF(ISNUMBER(G22),G22/C22,"TBD") -> 45300 | J22: =$J$10*D22 -> 23429.742 | K22: =$K$10*D22 -> 9371.8969 | L22: =$L$10*D22 -> 3.6515916 | M22: =$M$10*$D22 -> 5.5237274 | N22: =$N$10*D22 -> 1259342 | O22: =$O$10*$D22 -> 19041.409 | P22: =$P$10*$D22 -> 33447.27 | Q22: =$Q$10*$D22 -> 0 | R22: =$R$10*$D22 -> 56578.749 | S22: =$S$10*$D22 -> 8991708.3 | T22: =$T$10*$D22 -> 6617692
A23: ='Property Value Estimates'!A22 -> 3550 | B23: ='Property Value Estimates'!B22 -> Office | C23: ='Property Value Estimates'!G22 -> 875.3904 | D23: =C23/$C$35 -> 0.034578632 | E23: ='Property Value Estimates'!N22 -> Reconstruct | F23: =IFERROR(VLOOKUP(E23,$A$7:$D$9,4,FALSE()),"TBD") -> 302000 | G23: =IF(ISNUMBER(F23),C23*F23,"TBD") -> 2.643679e+08 | H23: =IF(ISNUMBER(G23),G23/1000000,"TBD") -> 264.3679 | I23: =IF(ISNUMBER(G23),G23/C23,"TBD") -> 302000 | J23: =$J$10*D23 -> 43707.841 | K23: =$K$10*D23 -> 17483.136 | L23: =$L$10*D23 -> 6.8119906 | M23: =$M$10*$D23 -> 10.304432 | N23: =$N$10*D23 -> 2349284 | O23: =$O$10*$D23 -> 35521.47 | P23: =$P$10*$D23 -> 62395.391 | Q23: =$Q$10*$D23 -> 0 | R23: =$R$10*$D23 -> 105546.83 | S23: =$S$10*$D23 -> 16773900 | T23: =$T$10*$D23 -> 12345207
A24: ='Property Value Estimates'!A23 -> 3552 | B24: ='Property Value Estimates'!B23 -> Residence & Commercial Mixed | C24: ='Property Value Estimates'!G23 -> 109.3164 | D24: =C24/$C$35 -> 0.0043180867 | E24: ='Property Value Estimates'!N23 -> Maintenance | F24: =IFERROR(VLOOKUP(E24,$A$7:$D$9,4,FALSE()),"TBD") -> 45300 | G24: =IF(ISNUMBER(F24),C24*F24,"TBD") -> 4952032.9 | H24: =IF(ISNUMBER(G24),G24/1000000,"TBD") -> 4.9520329 | I24: =IF(ISNUMBER(G24),G24/C24,"TBD") -> 45300 | J24: =$J$10*D24 -> 5458.1177 | K24: =$K$10*D24 -> 2183.2471 | L24: =$L$10*D24 -> 0.85066307 | M24: =$M$10*$D24 -> 1.2867898 | N24: =$N$10*D24 -> 293372.27 | O24: =$O$10*$D24 -> 4435.8257 | P24: =$P$10*$D24 -> 7791.7687 | Q24: =$Q$10*$D24 -> 0 | R24: =$R$10*$D24 -> 13180.404 | S24: =$S$10*$D24 -> 2094679.5 | T24: =$T$10*$D24 -> 1541636.3
... A34: ='Property Value Estimates'!A33 -> 5050 | B34: ='Property Value Estimates'!B33 -> Office | C34: ='Property Value Estimates'!G33 -> 292.51969 | D34: =C34/$C$35 -> 0.011554766 | E34: ='Property Value Estimates'!N33 -> Reconstruct | F34: =IFERROR(VLOOKUP(E34,$A$7:$D$9,4,FALSE()),"TBD") -> 302000 | G34: =IF(ISNUMBER(F34),C34*F34,"TBD") -> 88340947 | H34: =IF(ISNUMBER(G34),G34/1000000,"TBD") -> 88.340947 | I34: =IF(ISNUMBER(G34),G34/C34,"TBD") -> 302000 | J34: =$J$10*D34 -> 14605.374 | K34: =$K$10*D34 -> 5842.1496 | L34: =$L$10*D34 -> 2.2762888 | M34: =$M$10*$D34 -> 3.4433201 | N34: =$N$10*D34 -> 785034.7 | O34: =$O$10*$D34 -> 11869.823 | P34: =$P$10*$D34 -> 20849.989 | Q34: =$Q$10*$D34 -> 0 | R34: =$R$10*$D34 -> 35269.435 | S34: =$S$10*$D34 -> 5605151.8 | T34: =$T$10*$D34 -> 4125263.8
A35: TOTAL | C35: =SUM(C13:C34) -> 25315.935 | D35: =C35/$C$35 -> 1 | G35: =SUMIF(G13:G34,"<>TBD") -> 3.7754291e+09 | H35: =SUMIF(H13:H34,"<>TBD") -> 3775.4291 | J35: =$J$10*D35 -> 1264013 | K35: =$K$10*D35 -> 505605.2 | L35: =$L$10*D35 -> 197 | M35: =$M$10*$D35 -> 298 | N35: =$N$10*D35 -> 67940340 | O35: =$O$10*$D35 -> 1027266.5 | P35: =$P$10*$D35 -> 1804449.4 | Q35: =$Q$10*$D35 -> 0 | R35: =$R$10*$D35 -> 3052371.3 | S35: =$S$10*$D35 -> 4.8509437e+08 | T35: =$T$10*$D35 -> 3.5701839e+08
A36: Note: TBD = tier not yet determined (3 unmatched buildings, see Building Age & Tier sheet). TBD buildings are excluded from cost totals until a Built Year is entered.
A38: SUMMARY BY TIER
A39: Tier | B39: Count | C39: Total GFA (m²) | D39: Unit Cost (¥/m²) | E39: Total Cost (¥M)
A40: Reconstruct | B40: =COUNTIF($E$13:$E$34,A40) -> 5 | C40: =SUMIF($E$13:$E$34,A40,$C$13:$C$34) -> 5890.3792 | D40: =IFERROR(VLOOKUP(A40,$A$7:$D$9,4,FALSE()),"-") -> 302000 | E40: =SUMIF($E$13:$E$34,A40,$H$13:$H$34) -> 1778.8945
A41: Renovate | B41: =COUNTIF($E$13:$E$34,A41) -> 9 | C41: =SUMIF($E$13:$E$34,A41,$C$13:$C$34) -> 14120.467 | D41: =IFERROR(VLOOKUP(A41,$A$7:$D$9,4,FALSE()),"-") -> 135900 | E41: =SUMIF($E$13:$E$34,A41,$H$13:$H$34) -> 1918.9715
A42: Maintenance | B42: =COUNTIF($E$13:$E$34,A42) -> 5 | C42: =SUMIF($E$13:$E$34,A42,$C$13:$C$34) -> 1712.2075 | D42: =IFERROR(VLOOKUP(A42,$A$7:$D$9,4,FALSE()),"-") -> 45300 | E42: =SUMIF($E$13:$E$34,A42,$H$13:$H$34) -> 77.563
A43: TBD | B43: =COUNTIF($E$13:$E$34,A43) -> 3 | C43: =SUMIF($E$13:$E$34,A43,$C$13:$C$34) -> 3592.8806 | D43: - | E43: TBD
A44: TOTAL | B44: =SUM(B40:B43) -> 22 | C44: =SUM(C40:C43) -> 25315.935 | E44: =SUMIF(E40:E43,"<>TBD") -> 3775.4291
A46: METHODOLOGY NOTES
A47: Reconstruction unit cost (¥302,000/m²) is the MLIT 2022 detached-house survey prefab/steel-frame average (¥302,655/m²),
A48: used as a proxy for steel/RC office new-build. Edit cell E4 to substitute a building-specific or escalated figure.
A49: Renovation = 45% and Maintenance = 15% of the reconstruction unit cost (editable in C8 / C9). Ratios reflect scope:
A50: Renovation covers envelope (R-value/U-value/WWR) + HVAC + programmatic change; Maintenance covers minor envelope,
A51: lighting, HVAC tuning, and optional PV. Both preserve the ordering Reconstruct > Renovate > Maintenance.
A52: Cost escalation: 2015-base construction indices (kentiku files) sit ~1.42–1.45x in 2026; the ¥302,000/m² figure is treated
...

Sheet Graph Examples
A1: Include | B1: Include | C1: Include | D1: NOT INCLUDE | E1: Include | F1: NOT INCLUDE | G1: NOT INCLUDE | H1: Include | I1: NOT INCLUDE | J1: Include | K1: Include | L1: Include | M1: Include | N1: Include | O1: Include | P1: Include | Q1: NOT INCLUDE | R1: Include | S1: Include | T1: Include
A2: ID | B2: Use Type | C2: GFA (m²) | D2: Share of total Area | E2: Tier (Age-Based) | F2: Unit Cost (¥/m²) | G2: Est. Revitalization Cost (¥) | H2: Est. Cost (¥M) | I2: Cost per m² check | J2: Annual Energy (kWh) | K2: Annual Renewable Energy | L2: Emmissions with DER | M2: Emmissions without DER | N2: DER Captial Expenditures | O2: Bill with DER | P2: Bill without DER | Q2: Operation & Maintenance Cost W/O DER | R2: Operation & Maintenance Cost of DER | S2: Without DER | T2: With DER
A3: 2070 | B3: Office | C3: 410.5 | D3: 0.0162 | E3: Maintenance | F3: ¥45,300 | G3: ¥18,597,281 | H3: 18.6 | I3: ¥45,300 | J3: 20497.87 | K3: 8199.15 | L3: 3.19 | M3: 4.83 | N3: ¥ 1,101,754.91 | O3: 16658.67 | P3: 29261.86 | Q3: ¥ - | R3: 49498.8 | S3: 7866535.7 | T3: 5789590.7

Sheet Sheet1
A1: Energy Bill W/DER | B1: Energy Bill W/O DER
A2: 16658.67 | B2: 29261.86
